<?xml version="1.0" ?>
<robot name="indy_dual_arm" xmlns:xacro="http://www.ros.org/wiki/xacro">

	<material name="black">
    <color rgba="0.0 0.0 0.0 1.0"/>
  </material>
  <material name="blue">
    <color rgba="0.0 0.0 0.8 1.0"/>
  </material>
  <material name="green">
    <color rgba="0.0 0.8 0.0 1.0"/>
  </material>
  <material name="grey">
    <color rgba="0.2 0.2 0.2 1.0"/>
  </material>
  <material name="orange">
    <color rgba="1.0 0.423529411765 0.0392156862745 1.0"/>
  </material>
  <material name="brown">
    <color rgba="0.870588235294 0.811764705882 0.764705882353 1.0"/>
  </material>
  <material name="red">
    <color rgba="0.8 0.0 0.0 1.0"/>
  </material>
  <material name="white">
    <color rgba="1.0 1.0 1.0 1.0"/>
  </material>
  <material name="metal">
    <color rgba="0.768627450980392 0.749019607843137 0.729411764705882 1"/>
  </material>
  <material name="metal_grey">
    <color rgba="0.501960784313725 0.501960784313725 0.501960784313725 1"/>
  </material>
  <material name="metal_white">
    <color rgba="0.866666666666667 0.866666666666667 0.890196078431373 1"/>
  </material>


	<link name="r_0">
		<inertial>
			<origin xyz="0 0 0" rpy="0 0 0"/>
			<mass value="1.59306955"/>
			<inertia ixx="+0.00572623" iyy="+0.00558959" izz="+0.00966674" ixy="+0.00000251" iyz="-0.00000014" ixz="-0.00011380"/>
		</inertial>
		<visual>
			<origin rpy="0 0 0" xyz="0 0 0"/>
			<geometry>
				<mesh filename="meshes/collision/Indy7_0.stl"/>
			</geometry>
	        <material name="metal_grey"/>

		</visual>
		<collision>
			<origin rpy="0 0 0" xyz="0 0 0"/>
			<geometry>
				<mesh filename="meshes/collision/Indy7_0.stl"/>
			</geometry>
		</collision>

	</link>
	<link name="r_1">
		<inertial>
			<origin xyz="0 0 0" rpy="0 0 0"/>
			<mass value="11.8030102"/>
			<inertia ixx="+0.15418559" iyy="+0.12937017" izz="+0.05964415" ixy="-0.00000235" iyz="-0.04854267" ixz="+0.00001739"/>
		</inertial>
		<visual>
			<origin rpy="0 0 0" xyz="0 0 0"/>
			<geometry>
				<mesh filename="meshes/collision/Indy7_1.stl"/>
			</geometry>
		</visual>
		<collision>
			<origin rpy="0 0 0" xyz="0 0 0"/>
			<geometry>
				<mesh filename="meshes/collision/Indy7_1.stl"/>
			</geometry>
		</collision>
	</link>
	<link name="r_2">
		<inertial>
			<origin xyz="0 0 0" rpy="0 0 0"/>
			<mass value="7.99292141"/>
			<inertia ixx="+0.29356980" iyy="+0.28094142" izz="+0.03620609" ixy="-0.00000040" iyz="+0.03727972" ixz="+0.00001441"/>
		</inertial>
		<visual>
			<origin rpy="0 0 0" xyz="0 0 0"/>
			<geometry>
				<mesh filename="meshes/collision/Indy7_2.stl"/>
			</geometry>
		</visual>
		<collision>
			<origin rpy="0 0 0" xyz="0 0 0"/>
			<geometry>
				<mesh filename="meshes/collision/Indy7_2.stl"/>
			</geometry>
		</collision>
	</link>
	<link name="r_3">
		<inertial>
			<origin xyz="0 0 0" rpy="0 0 0"/>
			<mass value="2.99134127"/>
			<inertia ixx="+0.03424593" iyy="+0.03406024" izz="+0.00450477" ixy="+0.00000149" iyz="+0.00186009" ixz="+0.00000724"/>
		</inertial>
		<visual>
			<origin rpy="0 0 0" xyz="0 0 0"/>
			<geometry>
				<mesh filename="meshes/collision/Indy7_3.stl"/>
			</geometry>
		</visual>
		<collision>
			<origin rpy="0 0 0" xyz="0 0 0"/>
			<geometry>
				<mesh filename="meshes/collision/Indy7_3.stl"/>
			</geometry>
		</collision>
	</link>
	<link name="r_4">
		<inertial>
			<origin xyz="0 0 0" rpy="0 0 0"/>
			<mass value="2.12317035"/>
			<inertia ixx="+0.00670405" iyy="+0.00279246" izz="+0.00619341" ixy="+0.00000375" iyz="-0.00127967" ixz="+0.00000150"/>
		</inertial>
		<visual>
			<origin rpy="0 0 0" xyz="0 0 0"/>
			<geometry>
				<mesh filename="meshes/collision/Indy7_4.stl"/>
			</geometry>
		</visual>
		<collision>
			<origin rpy="0 0 0" xyz="0 0 0"/>
			<geometry>
				<mesh filename="meshes/collision/Indy7_4.stl"/>
			</geometry>
		</collision>
	</link>
	<link name="r_5">
		<inertial>
			<origin xyz="0 0 0" rpy="0 0 0"/>
			<mass value="2.28865091"/>
			<inertia ixx="+0.00994891" iyy="+0.00978189" izz="+0.00271492" ixy="+0.00000014" iyz="-0.00093546" ixz="+0.00000321"/>
		</inertial>
		<visual>
			<origin rpy="0 0 0" xyz="0 0 0"/>
			<geometry>
				<mesh filename="meshes/collision/Indy7_5.stl"/>
			</geometry>
		</visual>
		<collision>
			<origin rpy="0 0 0" xyz="0 0 0"/>
			<geometry>
				<mesh filename="meshes/collision/Indy7_5.stl"/>
			</geometry>
		</collision>
	</link>
	<link name="r_6">
		<inertial>
			<origin xyz="0 0 0" rpy="0 0 0"/>
			<mass value="0.40083918"/>
			<inertia ixx="0.00043534" iyy="0.00044549" izz="0.00059634" ixy="+0.00000013" iyz="+0.00000051" ixz="-0.00000002"/>
		</inertial>
		<visual>
			<origin rpy="0 0 0" xyz="0 0 0"/>
			<geometry>
				<mesh filename="meshes/collision/Indy7_6.stl"/>
			</geometry>
		</visual>
		<collision>
			<origin rpy="0 0 0" xyz="0 0 0"/>
			<geometry>
				<mesh filename="meshes/collision/Indy7_6.stl"/>
			</geometry>
		</collision>
	</link>

	<link name="r_eef"/>


<!-- --------------------------------------------------------------------------------------------------------------------------------------- -->



	<joint name="r_joint_0" type="revolute">
 		<origin rpy="0 0 0" xyz="0 0 0.0775"/>
		<axis xyz="0 0 1"/>
 		<parent link="r_0"/>
		<child link="r_1"/>
		<limit effort="100" velocity="10" lower="-3.054325556" upper="3.054325556"/>	

 	</joint>
  	<joint name="r_joint_1" type="revolute">
 		<origin rpy="1.5707 1.5707 0" xyz="0 -0.109 0.222"/>
		<axis xyz="0 0 1"/>
 		<parent link="r_1"/>
		<child link="r_2"/>
		<limit effort="100" velocity="10" lower="-3.054325556" upper="3.054325556"/>		
 	</joint>
  	<joint name="r_joint_2" type="revolute">
 		<origin rpy="0 0 0" xyz="-0.45 0 -0.0305"/>
		<axis xyz="0 0 1"/>
 		<parent link="r_2"/>
		<child link="r_3"/>
		<limit effort="100" velocity="10" lower="-3.054325556" upper="3.054325556"/>		
 	</joint>
  	<joint name="r_joint_3" type="revolute">
 		<origin rpy="-1.5707 0 1.5707" xyz="-0.267 0 -0.075"/>
		<axis xyz="0 0 1"/>
 		<parent link="r_3"/>
		<child link="r_4"/>
		<limit effort="100" velocity="10" lower="-3.054325556" upper="3.054325556"/>		

 	</joint>
  	<joint name="r_joint_4" type="revolute">
 		<origin rpy="1.5707 1.5707 0" xyz="0 -0.114 0.083"/>
		<axis xyz="0 0 1"/>
 		<parent link="r_4"/>
		<child link="r_5"/>
		<limit effort="100" velocity="10" lower="-3.054325556" upper="3.054325556"/>		

 	</joint>
  	<joint name="r_joint_5" type="revolute">
 		<origin rpy="-1.5707 0 1.5707" xyz="-0.168 0 0.069"/>
		<axis xyz="0 0 1"/>
 		<parent link="r_5"/>
		<child link="r_6"/>
		<limit effort="100" velocity="10" lower="-3.752457111" upper="3.752457111"/>		

 	</joint>


  	<joint name="r_fixed_eef" type="fixed">
 		<origin rpy="0 0 0" xyz="0 0 0.06"/>
		<axis xyz="0 0 1"/>
 		<parent link="r_6"/>
		<child link="r_eef"/>
 	</joint>



 	<!-- ------------------------------------------------------------------------ -->


  
</robot>
