<?xml version="1.0" ?>
<robot name="indy_dual_arm" xmlns:xacro="http://www.ros.org/wiki/xacro">

	<material name="black">
    <color rgba="0.0 0.0 0.0 1.0"/>
  </material>
  <material name="blue">
    <color rgba="0.0 0.0 0.8 1.0"/>
  </material>
  <material name="green">
    <color rgba="0.0 0.8 0.0 1.0"/>
  </material>
  <material name="grey">
    <color rgba="0.2 0.2 0.2 1.0"/>
  </material>
  <material name="orange">
    <color rgba="1.0 0.423529411765 0.0392156862745 1.0"/>
  </material>
  <material name="brown">
    <color rgba="0.870588235294 0.811764705882 0.764705882353 1.0"/>
  </material>
  <material name="red">
    <color rgba="0.8 0.0 0.0 1.0"/>
  </material>
  <material name="white">
    <color rgba="1.0 1.0 1.0 1.0"/>
  </material>
  <material name="metal">
    <color rgba="0.768627450980392 0.749019607843137 0.729411764705882 1"/>
  </material>
  <material name="metal_grey">
    <color rgba="0.501960784313725 0.501960784313725 0.501960784313725 1"/>
  </material>
  <material name="metal_white">
    <color rgba="0.866666666666667 0.866666666666667 0.890196078431373 1"/>
  </material>


	<link name="world"/>
	<link name="body">
		<inertial>
			<origin rpy="0 0 0" xyz="0 0 0"/>
			<mass value="1.59306955" />
			<inertia ixx="+0.00572623" iyy="+0.00558959" izz="+0.00966674" ixy="+0.00000251" iyz="-0.00000014" ixz="-0.00011380"/>
		</inertial>
		<visual>
			<origin rpy="0 0 0" xyz="0 0 0"/>
			<geometry>
				<mesh filename="meshes/visual/body.stl"/>
			</geometry>
	        <material name="metal_grey"/>

		</visual>
		<collision>
			<origin rpy="0 0 0" xyz="0 0 0"/>
			<geometry>
				<mesh filename="meshes/visual/body.stl"/>
			</geometry>
		</collision>
	</link>
	<link name="camera">
		<inertial>
			<origin rpy="0 0 0" xyz="0 0 0"/>
			<mass value="0.0" />
			<inertia ixx="+0.000" iyy="+0.0" izz="+0.0" ixy="+0.0" iyz="0.00" ixz="-0.00"/>
		</inertial>
		<visual>
			<origin rpy="0 0 0" xyz="0 0 0"/>
			<geometry>
				<mesh filename="meshes/visual/camera.stl"/>
			</geometry>
	        <material name="metal_white"/>

		</visual>
		<collision>
			<origin rpy="0 0 0" xyz="0 0 0"/>
			<geometry>
				<mesh filename="meshes/visual/camera.stl"/>
			</geometry>
		</collision>
	</link>
	<link name="r_0">
		<inertial>
			<origin xyz="0 0 0" rpy="0 0 0"/>
			<mass value="1.59306955"/>
			<inertia ixx="+0.00572623" iyy="+0.00558959" izz="+0.00966674" ixy="+0.00000251" iyz="-0.00000014" ixz="-0.00011380"/>
		</inertial>
		<visual>
			<origin rpy="0 0 0" xyz="0 0 0"/>
			<geometry>
				<mesh filename="meshes/collision/Indy7_0.stl"/>
			</geometry>
	        <material name="metal_grey"/>

		</visual>
		<collision>
			<origin rpy="0 0 0" xyz="0 0 0"/>
			<geometry>
				<mesh filename="meshes/collision/Indy7_0.stl"/>
			</geometry>
		</collision>

	</link>
	<link name="r_1">
		<inertial>
			<origin xyz="0 0 0" rpy="0 0 0"/>
			<mass value="11.8030102"/>
			<inertia ixx="+0.15418559" iyy="+0.12937017" izz="+0.05964415" ixy="-0.00000235" iyz="-0.04854267" ixz="+0.00001739"/>
		</inertial>
		<visual>
			<origin rpy="0 0 0" xyz="0 0 0"/>
			<geometry>
				<mesh filename="meshes/collision/Indy7_1.stl"/>
			</geometry>
		</visual>
		<collision>
			<origin rpy="0 0 0" xyz="0 0 0"/>
			<geometry>
				<mesh filename="meshes/collision/Indy7_1.stl"/>
			</geometry>
		</collision>
	</link>
	<link name="r_2">
		<inertial>
			<origin xyz="0 0 0" rpy="0 0 0"/>
			<mass value="7.99292141"/>
			<inertia ixx="+0.29356980" iyy="+0.28094142" izz="+0.03620609" ixy="-0.00000040" iyz="+0.03727972" ixz="+0.00001441"/>
		</inertial>
		<visual>
			<origin rpy="0 0 0" xyz="0 0 0"/>
			<geometry>
				<mesh filename="meshes/collision/Indy7_2.stl"/>
			</geometry>
		</visual>
		<collision>
			<origin rpy="0 0 0" xyz="0 0 0"/>
			<geometry>
				<mesh filename="meshes/collision/Indy7_2.stl"/>
			</geometry>
		</collision>
	</link>
	<link name="r_3">
		<inertial>
			<origin xyz="0 0 0" rpy="0 0 0"/>
			<mass value="2.99134127"/>
			<inertia ixx="+0.03424593" iyy="+0.03406024" izz="+0.00450477" ixy="+0.00000149" iyz="+0.00186009" ixz="+0.00000724"/>
		</inertial>
		<visual>
			<origin rpy="0 0 0" xyz="0 0 0"/>
			<geometry>
				<mesh filename="meshes/collision/Indy7_3.stl"/>
			</geometry>
		</visual>
		<collision>
			<origin rpy="0 0 0" xyz="0 0 0"/>
			<geometry>
				<mesh filename="meshes/collision/Indy7_3.stl"/>
			</geometry>
		</collision>
	</link>
	<link name="r_4">
		<inertial>
			<origin xyz="0 0 0" rpy="0 0 0"/>
			<mass value="2.12317035"/>
			<inertia ixx="+0.00670405" iyy="+0.00279246" izz="+0.00619341" ixy="+0.00000375" iyz="-0.00127967" ixz="+0.00000150"/>
		</inertial>
		<visual>
			<origin rpy="0 0 0" xyz="0 0 0"/>
			<geometry>
				<mesh filename="meshes/collision/Indy7_4.stl"/>
			</geometry>
		</visual>
		<collision>
			<origin rpy="0 0 0" xyz="0 0 0"/>
			<geometry>
				<mesh filename="meshes/collision/Indy7_4.stl"/>
			</geometry>
		</collision>
	</link>
	<link name="r_5">
		<inertial>
			<origin xyz="0 0 0" rpy="0 0 0"/>
			<mass value="2.28865091"/>
			<inertia ixx="+0.00994891" iyy="+0.00978189" izz="+0.00271492" ixy="+0.00000014" iyz="-0.00093546" ixz="+0.00000321"/>
		</inertial>
		<visual>
			<origin rpy="0 0 0" xyz="0 0 0"/>
			<geometry>
				<mesh filename="meshes/collision/Indy7_5.stl"/>
			</geometry>
		</visual>
		<collision>
			<origin rpy="0 0 0" xyz="0 0 0"/>
			<geometry>
				<mesh filename="meshes/collision/Indy7_5.stl"/>
			</geometry>
		</collision>
	</link>
	<link name="r_6">
		<inertial>
			<origin xyz="0 0 0" rpy="0 0 0"/>
			<mass value="0.40083918"/>
			<inertia ixx="0.00043534" iyy="0.00044549" izz="0.00059634" ixy="+0.00000013" iyz="+0.00000051" ixz="-0.00000002"/>
		</inertial>
		<visual>
			<origin rpy="0 0 0" xyz="0 0 0"/>
			<geometry>
				<mesh filename="meshes/collision/Indy7_6.stl"/>
			</geometry>
		</visual>
		<collision>
			<origin rpy="0 0 0" xyz="0 0 0"/>
			<geometry>
				<mesh filename="meshes/collision/Indy7_6.stl"/>
			</geometry>
		</collision>
	</link>
	<link name="l_0">
		<inertial>
			<origin xyz="0 0 0" rpy="0 0 0"/>
			<mass value="1.59306955"/>
			<inertia ixx="+0.00572623" iyy="+0.00558959" izz="+0.00966674" ixy="+0.00000251" iyz="-0.00000014" ixz="-0.00011380"/>
		</inertial>
		<visual>
			<origin rpy="0 0 0" xyz="0 0 0"/>
			<geometry>
				<mesh filename="meshes/collision/Indy7_0.stl"/>
			</geometry>
	        <material name="metal_grey"/>

		</visual>
		<collision>
			<origin rpy="0 0 0" xyz="0 0 0"/>
			<geometry>
				<mesh filename="meshes/collision/Indy7_0.stl"/>
			</geometry>
		</collision>

	</link>
	<link name="l_1">
		<inertial>
			<origin xyz="0 0 0" rpy="0 0 0"/>
			<mass value="11.8030102"/>
			<inertia ixx="+0.15418559" iyy="+0.12937017" izz="+0.05964415" ixy="-0.00000235" iyz="-0.04854267" ixz="+0.00001739"/>
		</inertial>
		<visual>
			<origin rpy="0 0 0" xyz="0 0 0"/>
			<geometry>
				<mesh filename="meshes/collision/Indy7_1.stl"/>
			</geometry>
		</visual>
		<collision>
			<origin rpy="0 0 0" xyz="0 0 0"/>
			<geometry>
				<mesh filename="meshes/collision/Indy7_1.stl"/>
			</geometry>
		</collision>
	</link>
	<link name="l_2">
		<inertial>
			<origin xyz="0 0 0" rpy="0 0 0"/>
			<mass value="7.99292141"/>
			<inertia ixx="+0.29356980" iyy="+0.28094142" izz="+0.03620609" ixy="-0.00000040" iyz="+0.03727972" ixz="+0.00001441"/>
		</inertial>
		<visual>
			<origin rpy="0 0 0" xyz="0 0 0"/>
			<geometry>
				<mesh filename="meshes/collision/Indy7_2.stl"/>
			</geometry>
		</visual>
		<collision>
			<origin rpy="0 0 0" xyz="0 0 0"/>
			<geometry>
				<mesh filename="meshes/collision/Indy7_2.stl"/>
			</geometry>
		</collision>
	</link>
	<link name="l_3">
		<inertial>
			<origin xyz="0 0 0" rpy="0 0 0"/>
			<mass value="2.99134127"/>
			<inertia ixx="+0.03424593" iyy="+0.03406024" izz="+0.00450477" ixy="+0.00000149" iyz="+0.00186009" ixz="+0.00000724"/>
		</inertial>
		<visual>
			<origin rpy="0 0 0" xyz="0 0 0"/>
			<geometry>
				<mesh filename="meshes/collision/Indy7_3.stl"/>
			</geometry>
		</visual>
		<collision>
			<origin rpy="0 0 0" xyz="0 0 0"/>
			<geometry>
				<mesh filename="meshes/collision/Indy7_3.stl"/>
			</geometry>
		</collision>
	</link>
	<link name="l_4">
		<inertial>
			<origin xyz="0 0 0" rpy="0 0 0"/>
			<mass value="2.12317035"/>
			<inertia ixx="+0.00670405" iyy="+0.00279246" izz="+0.00619341" ixy="+0.00000375" iyz="-0.00127967" ixz="+0.00000150"/>
		</inertial>
		<visual>
			<origin rpy="0 0 0" xyz="0 0 0"/>
			<geometry>
				<mesh filename="meshes/collision/Indy7_4.stl"/>
			</geometry>
		</visual>
		<collision>
			<origin rpy="0 0 0" xyz="0 0 0"/>
			<geometry>
				<mesh filename="meshes/collision/Indy7_4.stl"/>
			</geometry>
		</collision>
	</link>
	<link name="l_5">
		<inertial>
			<origin xyz="0 0 0" rpy="0 0 0"/>
			<mass value="2.28865091"/>
			<inertia ixx="+0.00994891" iyy="+0.00978189" izz="+0.00271492" ixy="+0.00000014" iyz="-0.00093546" ixz="+0.00000321"/>
		</inertial>
		<visual>
			<origin rpy="0 0 0" xyz="0 0 0"/>
			<geometry>
				<mesh filename="meshes/collision/Indy7_5.stl"/>
			</geometry>
		</visual>
		<collision>
			<origin rpy="0 0 0" xyz="0 0 0"/>
			<geometry>
				<mesh filename="meshes/collision/Indy7_5.stl"/>
			</geometry>
		</collision>
	</link>
	<link name="l_6">
		<inertial>
			<origin xyz="0 0 0" rpy="0 0 0"/>
			<mass value="0.40083918"/>
			<inertia ixx="0.00043534" iyy="0.00044549" izz="0.00059634" ixy="+0.00000013" iyz="+0.00000051" ixz="-0.00000002"/>
		</inertial>
		<visual>
			<origin rpy="0 0 0" xyz="0 0 0"/>
			<geometry>
				<mesh filename="meshes/collision/Indy7_6.stl"/>
			</geometry>
		</visual>
		<collision>
			<origin rpy="0 0 0" xyz="0 0 0"/>
			<geometry>
				<mesh filename="meshes/collision/Indy7_6.stl"/>
			</geometry>
		</collision>
	</link>

	<link name="r_eef"/>
	<link name="l_eef"/>

<!-- --------------------------------------------------------------------------------------------------------------------------------------- -->
 	<joint name="world_fixed" type="fixed">
 		<origin rpy="0 0 0" xyz="0 0 0"/>
 		<parent link="world"/>
		<child link="body"/>
 	</joint>
 	<joint name="l_body_fixed" type="fixed">
 		<origin rpy="-1.047197 0 0" xyz="0 0.15634 0.37722"/>
		<axis xyz="0 0 1"/>
 		<parent link="body"/>
		<child link="l_0"/>
 	</joint>
 	<joint name="r_body_fixed" type="fixed">
 		<origin rpy="-1.047197 0 3.141592" xyz="0 -0.15634 0.37722"/>
		<axis xyz="0 0 1"/>
 		<parent link="body"/>
		<child link="r_0"/>
 	</joint>
 	<joint name="camera_fixed" type="fixed">
 		<origin rpy="0 0.785398 0" xyz="0.15 -0.032 0.60966"/>
		<axis xyz="0 0 1"/>
 		<parent link="body"/>
		<child link="camera"/>
 	</joint>

	<joint name="r_joint_0" type="revolute">
 		<origin rpy="0 0 0" xyz="0 0 0.0775"/>
		<axis xyz="0 0 1"/>
 		<parent link="r_0"/>
		<child link="r_1"/>
		<limit effort="10" velocity="1" lower="-3.054325556" upper="3.054325556"/>		
 	</joint>
  	<joint name="r_joint_1" type="revolute">
 		<origin rpy="1.5707 1.5707 0" xyz="0 -0.109 0.222"/>
		<axis xyz="0 0 1"/>
 		<parent link="r_1"/>
		<child link="r_2"/>
		<limit effort="10" velocity="1" lower="-3.054325556" upper="3.054325556"/>		
 	</joint>
  	<joint name="r_joint_2" type="revolute">
 		<origin rpy="0 0 0" xyz="-0.45 0 -0.0305"/>
		<axis xyz="0 0 1"/>
 		<parent link="r_2"/>
		<child link="r_3"/>
		<limit effort="10" velocity="1" lower="-3.054325556" upper="3.054325556"/>		
 	</joint>
  	<joint name="r_joint_3" type="revolute">
 		<origin rpy="-1.5707 0 1.5707" xyz="-0.267 0 -0.075"/>
		<axis xyz="0 0 1"/>
 		<parent link="r_3"/>
		<child link="r_4"/>
		<limit effort="10" velocity="1" lower="-3.054325556" upper="3.054325556"/>		

 	</joint>
  	<joint name="r_joint_4" type="revolute">
 		<origin rpy="1.5707 1.5707 0" xyz="0 -0.114 0.083"/>
		<axis xyz="0 0 1"/>
 		<parent link="r_4"/>
		<child link="r_5"/>
		<limit effort="10" velocity="1" lower="-3.054325556" upper="3.054325556"/>		

 	</joint>
  	<joint name="r_joint_5" type="revolute">
 		<origin rpy="-1.5707 0 1.5707" xyz="-0.168 0 0.069"/>
		<axis xyz="0 0 1"/>
 		<parent link="r_5"/>
		<child link="r_6"/>
		<limit effort="10" velocity="1" lower="-3.752457111" upper="3.752457111"/>		

 	</joint>
	<joint name="l_joint_0" type="revolute">
 		<origin rpy="0 0 0" xyz="0 0 0.0775"/>
		<axis xyz="0 0 1"/>
 		<parent link="l_0"/>
		<child link="l_1"/>
		<limit effort="10" velocity="1" lower="-3.054325556" upper="3.054325556"/>		
<dynamics damping="0.7"/>
 	</joint>
  	<joint name="l_joint_1" type="revolute">
 		<origin rpy="1.5707 1.5707 0" xyz="0 -0.109 0.222"/>
		<axis xyz="0 0 1"/>
 		<parent link="l_1"/>
		<child link="l_2"/>
		<limit effort="10" velocity="1" lower="-3.054325556" upper="3.054325556"/>		
<dynamics damping="0.7"/>
 	</joint>
  	<joint name="l_joint_2" type="revolute">
 		<origin rpy="0 0 0" xyz="-0.45 0 -0.0305"/>
		<axis xyz="0 0 1"/>
 		<parent link="l_2"/>
		<child link="l_3"/>
		<limit effort="10" velocity="1" lower="-3.054325556" upper="3.054325556"/>		
<dynamics damping="0.7"/>
 	</joint>
  	<joint name="l_joint_3" type="revolute">
 		<origin rpy="-1.5707 0 1.5707" xyz="-0.267 0 -0.075"/>
		<axis xyz="0 0 1"/>
 		<parent link="l_3"/>
		<child link="l_4"/>
		<limit effort="10" velocity="1" lower="-3.054325556" upper="3.054325556"/>		
		<dynamics damping="0.7"/>
 	</joint>
  	<joint name="l_joint_4" type="revolute">
 		<origin rpy="1.5707 1.5707 0" xyz="0 -0.114 0.083"/>
		<axis xyz="0 0 1"/>
 		<parent link="l_4"/>
		<child link="l_5"/>
		<limit effort="10" velocity="1" lower="-3.054325556" upper="3.054325556"/>		
		<dynamics damping="0.7"/>
 	</joint>
  	<joint name="l_joint_5" type="revolute">
 		<origin rpy="-1.5707 0 1.5707" xyz="-0.168 0 0.069"/>
		<axis xyz="0 0 1"/>
 		<parent link="l_5"/>
		<child link="l_6"/>
		<limit effort="10" velocity="1" lower="-3.752457111" upper="3.752457111"/>	
		<dynamics damping="0.7"/>	
 	</joint>
  	<joint name="l_fixed_eef" type="fixed">
 		<origin rpy="0 0 0" xyz="0 0 0.06"/>
		<axis xyz="0 0 1"/>
 		<parent link="l_6"/>
		<child link="l_eef"/>
 	</joint>
  	<joint name="r_fixed_eef" type="fixed">
 		<origin rpy="0 0 0" xyz="0 0 0.06"/>
		<axis xyz="0 0 1"/>
 		<parent link="r_6"/>
		<child link="r_eef"/>
 	</joint>
  	<joint name="r_fixed_gripper" type="fixed">
 		<origin rpy="0 0 0" xyz="0 0 0.01"/>
		<axis xyz="0 0 1"/>
 		<parent link="r_eef"/>
		<child link="r_rh_p12_rn_base"/>
 	</joint>
  	<joint name="l_fixed_gripper" type="fixed">
 		<origin rpy="0 0 0" xyz="0 0 0.01"/>
		<axis xyz="0 0 1"/>
 		<parent link="l_eef"/>
		<child link="l_rh_p12_rn_base"/>
 	</joint>

 	<!-- ------------------------------------------------------------------------ -->

  <link name="r_rh_p12_rn_base">
    <collision>
      <origin xyz="0 0 0" rpy="0 0 0"/>
      <geometry>
        <mesh filename="meshes/rh_p12_rn_a/base.stl" scale="0.001 0.001 0.001"/>
      </geometry>
    </collision>

    <visual>
      <origin xyz="0 0 0" rpy="0 0 0"/>
      <geometry>
        <mesh filename="meshes/rh_p12_rn_a/base.stl" scale="0.001 0.001 0.001"/>
      </geometry>
      <material name="grey"/>
    </visual>

    <inertial>
      <origin xyz="0.000 0.000 0.032" rpy="0 0 0"/>
      <mass value="0.236"/>
      <inertia ixx="0.00017" ixy="0.0" ixz="0.0" iyy="0.00011" iyz="0.0" izz="0.00017" />
      
    </inertial>
  </link>

  <!-- Joint -->
  <joint name="r_rh_p12_rn_a" type="revolute">
    <parent link="r_rh_p12_rn_base"/>
    <child link="r_rh_p12_rn_r1"/>
    <origin xyz="0.0 0.008 0.048" rpy="0 0 0"/>
    <axis xyz="1 0 0"/>
    <limit velocity="6.5" effort="1000" lower="0.0" upper="1.2" />
  </joint>

  <!-- rh_p12_rn_r1 -->
  <link name="r_rh_p12_rn_r1">
    <collision>
      <origin xyz="0 0 0" rpy="0 0 0"/>
      <geometry>
        <mesh filename="meshes/rh_p12_rn_a/r1.stl" scale="0.001 0.001 0.001"/>
      </geometry>
    </collision>

    <visual>
      <origin xyz="0 0 0" rpy="0 0 0"/>
      <geometry>
        <mesh filename="meshes/rh_p12_rn_a/r1.stl" scale="0.001 0.001 0.001"/>
      </geometry>
      <material name="grey"/>
    </visual>

    <inertial>
      <origin xyz="0.000 0.034 0.004" rpy="0 0 0"/>
      <mass value="0.068"/>
      <inertia ixx="0.00004" ixy="0.0" ixz="0.0" iyy="0.00002" iyz="-0.00001" izz="0.00002" />
      
    </inertial>
  </link>

  <!-- Right Joint 2 -->
  <joint name="r_rh_r2" type="revolute">
    <parent link="r_rh_p12_rn_r1"/>
    <child link="r_rh_p12_rn_r2"/>
    <origin xyz="0.0 0.0493634 0.0285" rpy="0 0 0"/>
    <axis xyz="-1 0 0"/>
    <limit velocity="6.5" effort="1000" lower="0.0" upper="1.2" />

  </joint>


  <!-- rh_p12_rn_r2 -->
  <link name="r_rh_p12_rn_r2">
    <collision>
      <origin xyz="0 0 0" rpy="0 0 0"/>
      <geometry>
        <mesh filename="meshes/rh_p12_rn_a/r2.stl" scale="0.001 0.001 0.001"/>
      </geometry>
    </collision>

    <visual>
      <origin xyz="0 0 0" rpy="0 0 0"/>
      <geometry>
        <mesh filename="meshes/rh_p12_rn_a/r2.stl" scale="0.001 0.001 0.001"/>
      </geometry>
      <material name="grey"/>
    </visual>

    <inertial>
      <origin xyz="0.000 0.006 0.011" rpy="0 0 0"/>
      <mass value="0.022"/>
      <inertia ixx="0.0" ixy="0.0" ixz="0.0" iyy="0.00001" iyz="0.0" izz="0.0" />
      
    </inertial>
  </link>

  <!-- Left Joint 1 -->
  <joint name="r_rh_l1" type="revolute">
    <parent link="r_rh_p12_rn_base"/>
    <child link="r_rh_p12_rn_l1"/>
    <origin xyz="0.0 -0.008 0.048" rpy="0 0 0"/>
    <axis xyz="-1 0 0"/>
    <limit velocity="6.5" effort="1000" lower="0.0" upper="1.2" />
  </joint>


  <!-- rh_p12_rn_l1 -->
  <link name="r_rh_p12_rn_l1">
    <collision>
      <origin xyz="0 0 0" rpy="0 0 0"/>
      <geometry>
        <mesh filename="meshes/rh_p12_rn_a/l1.stl" scale="0.001 0.001 0.001"/>
      </geometry>
    </collision>

    <visual>
      <origin xyz="0 0 0" rpy="0 0 0"/>
      <geometry>
        <mesh filename="meshes/rh_p12_rn_a/l1.stl" scale="0.001 0.001 0.001"/>
      </geometry>
      <material name="grey"/>
    </visual>

    <inertial>
      <origin xyz="0.000 -0.034 0.004" rpy="0 0 0"/>
      <mass value="0.068"/>
      <inertia ixx="0.00004" ixy="0.0" ixz="0.0" iyy="0.00002" iyz="0.00001" izz="0.00002" />
      
    </inertial>
  </link>

  <!-- Left Joint 2 -->
  <joint name="r_rh_l2" type="revolute">
    <parent link="r_rh_p12_rn_l1"/>
    <child link="r_rh_p12_rn_l2"/>
    <origin xyz="0.0 -0.0493634 0.0285" rpy="0 0 0"/>
    <axis xyz="1 0 0"/>
    <limit velocity="6.5" effort="1000" lower="0.0" upper="1.2" />

  </joint>


  <!-- rh_p12_rn_l2 -->
  <link name="r_rh_p12_rn_l2">
    <collision>
      <origin xyz="0 0 0" rpy="0 0 0"/>
      <geometry>
        <mesh filename="meshes/rh_p12_rn_a/l2.stl" scale="0.001 0.001 0.001"/>
      </geometry>
    </collision>

    <visual>
      <origin xyz="0 0 0" rpy="0 0 0"/>
      <geometry>
        <mesh filename="meshes/rh_p12_rn_a/l2.stl" scale="0.001 0.001 0.001"/>
      </geometry>
      <material name="grey"/>
    </visual>

    <inertial>
      <origin xyz="0.000 -0.006 0.011" rpy="0 0 0"/>
      <mass value="0.022"/>
      <inertia ixx="0.0" ixy="0.0" ixz="0.0" iyy="0.00001" iyz="0.0" izz="0.0" />
      
    </inertial>
  </link>

  <link name="l_rh_p12_rn_base">
    <collision>
      <origin xyz="0 0 0" rpy="0 0 0"/>
      <geometry>
        <mesh filename="meshes/rh_p12_rn_a/base.stl" scale="0.001 0.001 0.001"/>
      </geometry>
    </collision>

    <visual>
      <origin xyz="0 0 0" rpy="0 0 0"/>
      <geometry>
        <mesh filename="meshes/rh_p12_rn_a/base.stl" scale="0.001 0.001 0.001"/>
      </geometry>
      <material name="grey"/>
    </visual>

    <inertial>
      <origin xyz="0.000 0.000 0.032" rpy="0 0 0"/>
      <mass value="0.236"/>
      <inertia ixx="0.00017" ixy="0.0" ixz="0.0" iyy="0.00011" iyz="0.0" izz="0.00017" />
      
    </inertial>
  </link>

  <!-- Joint -->
  <joint name="l_rh_p12_rn_a" type="revolute">
    <parent link="l_rh_p12_rn_base"/>
    <child link="l_rh_p12_rn_r1"/>
    <origin xyz="0.0 0.008 0.048" rpy="0 0 0"/>
    <axis xyz="1 0 0"/>
    <limit velocity="6.5" effort="1000" lower="0.0" upper="1.2" />

  </joint>

  <!-- rh_p12_rn_r1 -->
  <link name="l_rh_p12_rn_r1">
    <collision>
      <origin xyz="0 0 0" rpy="0 0 0"/>
      <geometry>
        <mesh filename="meshes/rh_p12_rn_a/r1.stl" scale="0.001 0.001 0.001"/>
      </geometry>
    </collision>

    <visual>
      <origin xyz="0 0 0" rpy="0 0 0"/>
      <geometry>
        <mesh filename="meshes/rh_p12_rn_a/r1.stl" scale="0.001 0.001 0.001"/>
      </geometry>
      <material name="grey"/>
    </visual>

    <inertial>
      <origin xyz="0.000 0.034 0.004" rpy="0 0 0"/>
      <mass value="0.068"/>
      <inertia ixx="0.00004" ixy="0.0" ixz="0.0" iyy="0.00002" iyz="-0.00001" izz="0.00002" />
      
    </inertial>
  </link>

  <!-- Right Joint 2 -->
  <joint name="l_rh_r2" type="revolute">
    <parent link="l_rh_p12_rn_r1"/>
    <child link="l_rh_p12_rn_r2"/>
    <origin xyz="0.0 0.0493634 0.0285" rpy="0 0 0"/>
    <axis xyz="-1 0 0"/>
    <limit velocity="6.5" effort="1000" lower="0.0" upper="1.2" />
 
  </joint>


  <!-- rh_p12_rn_r2 -->
  <link name="l_rh_p12_rn_r2">
    <collision>
      <origin xyz="0 0 0" rpy="0 0 0"/>
      <geometry>
        <mesh filename="meshes/rh_p12_rn_a/r2.stl" scale="0.001 0.001 0.001"/>
      </geometry>
    </collision>

    <visual>
      <origin xyz="0 0 0" rpy="0 0 0"/>
      <geometry>
        <mesh filename="meshes/rh_p12_rn_a/r2.stl" scale="0.001 0.001 0.001"/>
      </geometry>
      <material name="grey"/>
    </visual>

    <inertial>
      <origin xyz="0.000 0.006 0.011" rpy="0 0 0"/>
      <mass value="0.022"/>
      <inertia ixx="0.0" ixy="0.0" ixz="0.0" iyy="0.00001" iyz="0.0" izz="0.0" />
      
    </inertial>
  </link>

  <!-- Left Joint 1 -->
  <joint name="l_rh_l1" type="revolute">
    <parent link="l_rh_p12_rn_base"/>
    <child link="l_rh_p12_rn_l1"/>
    <origin xyz="0.0 -0.008 0.048" rpy="0 0 0"/>
    <axis xyz="-1 0 0"/>
    <limit velocity="6.5" effort="1000" lower="0.0" upper="1.2" />
  
  </joint>


  <!-- rh_p12_rn_l1 -->
  <link name="l_rh_p12_rn_l1">
    <collision>
      <origin xyz="0 0 0" rpy="0 0 0"/>
      <geometry>
        <mesh filename="meshes/rh_p12_rn_a/l1.stl" scale="0.001 0.001 0.001"/>
      </geometry>
    </collision>

    <visual>
      <origin xyz="0 0 0" rpy="0 0 0"/>
      <geometry>
        <mesh filename="meshes/rh_p12_rn_a/l1.stl" scale="0.001 0.001 0.001"/>
      </geometry>
      <material name="grey"/>
    </visual>

    <inertial>
      <origin xyz="0.000 -0.034 0.004" rpy="0 0 0"/>
      <mass value="0.068"/>
      <inertia ixx="0.00004" ixy="0.0" ixz="0.0" iyy="0.00002" iyz="0.00001" izz="0.00002" />
      
    </inertial>
  </link>

  <!-- Left Joint 2 -->
  <joint name="l_rh_l2" type="revolute">
    <parent link="l_rh_p12_rn_l1"/>
    <child link="l_rh_p12_rn_l2"/>
    <origin xyz="0.0 -0.0493634 0.0285" rpy="0 0 0"/>
    <axis xyz="1 0 0"/>
    <limit velocity="6.5" effort="1000" lower="0.0" upper="1.2" />

  </joint>


  <!-- rh_p12_rn_l2 -->
  <link name="l_rh_p12_rn_l2">
    <collision>
      <origin xyz="0 0 0" rpy="0 0 0"/>
      <geometry>
        <mesh filename="meshes/rh_p12_rn_a/l2.stl" scale="0.001 0.001 0.001"/>
      </geometry>
    </collision>

    <visual>
      <origin xyz="0 0 0" rpy="0 0 0"/>
      <geometry>
        <mesh filename="meshes/rh_p12_rn_a/l2.stl" scale="0.001 0.001 0.001"/>
      </geometry>
      <material name="grey"/>
    </visual>

    <inertial>
      <origin xyz="0.000 -0.006 0.011" rpy="0 0 0"/>
      <mass value="0.022"/>
      <inertia ixx="0.0" ixy="0.0" ixz="0.0" iyy="0.00001" iyz="0.0" izz="0.0" />
      
    </inertial>
  </link>
</robot>
